
=================================== ERRORS ====================================
______________________ ERROR collecting test_ai_code.py _______________________
..\AppData\Local\Programs\Python\Python310\lib\site-packages\_pytest\python.py:498: in importtestmodule
    mod = import_path(
..\AppData\Local\Programs\Python\Python310\lib\site-packages\_pytest\pathlib.py:587: in import_path
    importlib.import_module(module_name)
..\AppData\Local\Programs\Python\Python310\lib\importlib\__init__.py:126: in import_module
    return _bootstrap._gcd_import(name[level:], package, level)
<frozen importlib._bootstrap>:1050: in _gcd_import
    ???
<frozen importlib._bootstrap>:1027: in _find_and_load
    ???
<frozen importlib._bootstrap>:1006: in _find_and_load_unlocked
    ???
<frozen importlib._bootstrap>:688: in _load_unlocked
    ???
..\AppData\Local\Programs\Python\Python310\lib\site-packages\_pytest\assertion\rewrite.py:186: in exec_module
    exec(co, module.__dict__)
test_ai_code.py:2: in <module>
    from ai_code import multiply_numbers
E     File "C:\Users\nkusu\AI_Code_Test\ai_code.py", line 1
E       def multiply_numbers(a, b)
E                                 ^
E   SyntaxError: expected ':'
=========================== short test summary info ===========================
ERROR test_ai_code.py
!!!!!!!!!!!!!!!!!!! Interrupted: 1 error during collection !!!!!!!!!!!!!!!!!!!!
1 error in 0.19s

************* Module ai_code
ai_code.py:1:27: E0001: Parsing failed: 'expected ':' (ai_code, line 1)' (syntax-error)
